{"statusDetails": {"trace": "self = <test_create_task_fails.TestFixture object at 0x0000022D07E4AA90>\n\n    @allure.severity(\"critical\")  # 优先级，包含blocker, critical, normal, minor, trivial 几个不同的等级\n    @allure.feature(\"测试模块_demo1\")  # 功能块，feature功能分块时比story大,即同时存在feature和story时,feature为父节点\n    @allure.story(\"测试模块_demo2\")  # 功能块，具有相同feature或story的用例将规整到相同模块下,执行时可用于筛选\n    @allure.issue(\"BUG号：123\")  # 问题表识，关联标识已有的问题，可为一个url链接地址\n    @allure.testcase(\"用例名：测试字符串相等\")  # 用例标识，关联标识用例，可为一个url链接地址\n    def test_create_task(self):\n        with allure.step(\"创建任务\"):\n            allure.attach(\"第一个步骤\",\"pass\")\n    \n        l = DateView(self.driver)\n        title=l.get_timestamp()\n        task=l.create_task(title)\n        expect (task==\"title\",\"任务名称错误\")\n        l.delete_task()\n>       assert_expectations()\n\n..\\test_case\\test_create_task_fails.py:29: \n_ _ _ _ _ _ _ _ _ _ _ _ _ _ _ _ _ _ _ _ _ _ _ _ _ _ _ _ _ _ _ _ _ _ _ _ _ _ _ _\n\n    def assert_expectations():\n        'raise an assert if there are any failed expectations'\n        if _failed_expectations:\n>           assert False, _report_failures()\nE           AssertionError: \nE           \nE           assert_expectations() called from\nE           \"test_create_task_fails.py\" line 29, in test_create_task()\nE           \nE           Failed Expectations:1\nE           \nE           1: file \"test_create_task_fails.py\", line 27, in test_create_task()\nE           任务名称错误\nE                   expect (task==\"title\",\"任务名称错误\")\n\n..\\common\\delayedAssert.py:37: AssertionError", "message": "AssertionError: \n\nassert_expectations() called from\n\"test_create_task_fails.py\" line 29, in test_create_task()\n\nFailed Expectations:1\n\n1: file \"test_create_task_fails.py\", line 27, in test_create_task()\n任务名称错误\n        expect (task==\"title\",\"任务名称错误\")"}, "name": "创建任务", "start": 1574691247682, "testCaseId": "b30e287c7babaa10c0ba26575440a1fc", "attachments": [{"source": "c0b6326f-0a8f-4ff2-8daf-6e9e20665435-attachment.txt", "name": "log", "type": "text/plain"}], "links": [{"url": "用例名：测试字符串相等", "type": "test_case", "name": "用例名：测试字符串相等"}, {"url": "BUG号：123", "type": "issue", "name": "BUG号：123"}], "historyId": "f87fd71c7504ef50bd2a5d7bec2a1691", "steps": [{"name": "创建任务", "start": 1574691247682, "status": "passed", "attachments": [{"source": "5b3a1443-c955-4bdc-96b8-70b63b6d602d-attachment.attach", "name": "pass"}], "stop": 1574691247685}, {"parameters": [{"value": "'1574691247'", "name": "title"}], "name": "创建任务", "start": 1574691247685, "status": "passed", "stop": 1574691265211}, {"name": "删除任务", "start": 1574691265591, "status": "passed", "stop": 1574691271734}], "labels": [{"value": "测试模块_demo1", "name": "feature"}, {"value": "critical", "name": "severity"}, {"value": "测试模块_demo2", "name": "story"}, {"value": "test_case", "name": "parentSuite"}, {"value": "TestFixture", "name": "subSuite"}, {"value": "test_create_task_fails", "name": "suite"}, {"value": "rachel", "name": "host"}, {"value": "4932-MainThread", "name": "thread"}, {"value": "pytest", "name": "framework"}, {"value": "cpython3", "name": "language"}, {"value": "test_case.test_create_task_fails", "name": "package"}], "stop": 1574691271782, "uuid": "cd18ded3-1a4a-4be8-8c92-fbdeee2cda07", "fullName": "test_case.test_create_task_fails.TestFixture#test_create_task", "status": "failed"}